Workbook

Sheet A faktisch
A1: Frage-ID | B1: Frage | C1: Modell | D1: It. | E1: Status | F1: Antwort (gekürzt) | G1: beste Zahl | H1: Sollwert | I1: Abw. % | J1: Wass muss stimmen? | K1: Bewertung
A2: E1_A01 | B2: How many rows (observations) does the dataset contain? Answer with the number only. | C2: gpt-5.6-luna | D2: 1 | E2: ok | F2: 1470 | G2: 1470 | H2: 1470 | I2: =ABS(G2-H2)/ABS(H2) -> 0 | J2: Anzahl Zeilen | K2: 2
A3: E1_A01 | B3: How many rows (observations) does the dataset contain? Answer with the number only. | C3: gpt-5.6-luna | D3: 2 | E3: ok | F3: 1470 | G3: 1470 | H3: 1470 | I3: =ABS(G3-H3)/ABS(H3) -> 0 | J3: Anzahl Zeilen | K3: 2
A4: E1_A01 | B4: How many rows (observations) does the dataset contain? Answer with the number only. | C4: gpt-5.6-luna | D4: 3 | E4: ok | F4: 1470 | G4: 1470 | H4: 1470 | I4: =ABS(G4-H4)/ABS(H4) -> 0 | J4: Anzahl Zeilen | K4: 2
A5: E1_A01 | B5: How many rows (observations) does the dataset contain? Answer with the number only. | C5: gpt-5.6-luna | D5: 4 | E5: ok | F5: 1470 | G5: 1470 | H5: 1470 | I5: =ABS(G5-H5)/ABS(H5) -> 0 | J5: Anzahl Zeilen | K5: 2
A6: E1_A01 | B6: How many rows (observations) does the dataset contain? Answer with the number only. | C6: gpt-5.6-luna | D6: 5 | E6: ok | F6: 1470 | G6: 1470 | H6: 1470 | I6: =ABS(G6-H6)/ABS(H6) -> 0 | J6: Anzahl Zeilen | K6: 2
A7: E1_A01 | B7: How many rows (observations) does the dataset contain? Answer with the number only. | C7: gemini-3.6-flash | D7: 1 | E7: ok | F7: 500 | G7: 500 | H7: 1470 | I7: =ABS(G7-H7)/ABS(H7) -> 0.65986395 | J7: Anzahl Zeilen | K7: 0
A8: E1_A01 | B8: How many rows (observations) does the dataset contain? Answer with the number only. | C8: gemini-3.6-flash | D8: 2 | E8: ok | F8: The dataset contains **500** rows (observations), excluding the header line. | G8: 500 | H8: 1470 | I8: =ABS(G8-H8)/ABS(H8) -> 0.65986395 | J8: Anzahl Zeilen | K8: 0
A9: E1_A01 | B9: How many rows (observations) does the dataset contain? Answer with the number only. | C9: gemini-3.6-flash | D9: 3 | E9: ABGESCHNITTEN | F9: c | G9: 0 | H9: 1470 | I9: =ABS(G9-H9)/ABS(H9) -> 1 | J9: Anzahl Zeilen | K9: 0
A10: E1_A01 | B10: How many rows (observations) does the dataset contain? Answer with the number only. | C10: gemini-3.6-flash | D10: 4 | E10: ok | F10: 1470 | G10: 1470 | H10: 1470 | I10: =ABS(G10-H10)/ABS(H10) -> 0 | J10: Anzahl Zeilen | K10: 2
A11: E1_A01 | B11: How many rows (observations) does the dataset contain? Answer with the number only. | C11: gemini-3.6-flash | D11: 5 | E11: ok | F11: 500 | G11: 500 | H11: 1470 | I11: =ABS(G11-H11)/ABS(H11) -> 0.65986395 | J11: Anzahl Zeilen | K11: 0
A12: E1_A02 | B12: What is the average monthly income (MonthlyIncome)? Answer with the number only. | C12: gpt-5.6-luna | D12: 1 | E12: ok | F12: 6502.93 | G12: 6502.93 | H12: 6502.93 | I12: =ABS(G12-H12)/ABS(H12) -> 0 | J12: numerischer Referenzwert (korrekt gerundet) und Abweichung <= 1% | K12: 2
A13: E1_A02 | B13: What is the average monthly income (MonthlyIncome)? Answer with the number only. | C13: gpt-5.6-luna | D13: 2 | E13: ok | F13: 6502.93 | G13: 6502.93 | H13: 6502.93 | I13: =ABS(G13-H13)/ABS(H13) -> 0 | J13: numerischer Referenzwert | K13: 2
... A57: E1_A06 | B57: How many outliers does the MonthlyIncome variable contain, based on the 1.5 IQR rule? Answer with the number only. | C57: gemini-3.6-flash | D57: 1 | E57: ok | F57: To determine the number of outliers in the `MonthlyIncome` variable using the 1.5 $\times$ IQR rule: 1. **Calculate the Quartiles:** * **First Quartile ($Q_1$):** 2,911 * **Third Quartile ($Q_3$):** 8,376 * **Interquartile Range ($\text{IQR}$):** $Q_3 - Q_1 = 8,376 - 2,911 = 5,465$ 2. **Calculate Outlier Thresholds:** * **Upper Bound:** $Q_3 + 1.5 \times \text{IQR} = 8,376 + 1.5 \times 5,465 = 16,573.5$ * **Lower Bound:** $Q_1 - 1.5 \times \text{IQR} = 2,911 - 1.5 \times 5,465 = -5,286.5$ 3. **Count the Outliers:** Any `MonthlyIncome` value greater than $16,573.5$ is consi … | G57: 50 | H57: 114 | I57: =ABS(G57-H57)/ABS(H57) -> 0.56140351 | J57: Anzahl nach exakt 1,5-IQR | K57: 0
A58: E1_A06 | B58: How many outliers does the MonthlyIncome variable contain, based on the 1.5 IQR rule? Answer with the number only. | C58: gemini-3.6-flash | D58: 2 | E58: ABGESCHNITTEN | F58: To determine the number of outliers for the `MonthlyIncome` variable using the 1.5 $\times$ IQR rule: 1. **Calculate the First Quartile ($Q_1$) and Third Quartile ($Q_3$):** * $Q_1 = 2,911$ * $Q_3 = 8,376$ 2. **Calculate the Interquartile Range ($\text{IQR}$):** * $\text{IQR} = Q_3 - Q_1 = 8,376 - 2,911 = 5,465$ 3. **Determine the Outlier Thresholds:** * **Upper Bound:** $Q_3 + 1.5 \times \text{IQR} = 8,376 + 1.5 \times 5,465 = 16,573.5$ * **Lower Bound:** $Q_1 - 1.5 \times \text{IQR} = 2,911 - 1.5 \times 5,465 = -5,286.5$ 4. **Identify Outliers:** * Values in `MonthlyInc … | G58: kein Endwert | H58: 114 | I58: 100 | J58: Anzahl nach exakt 1,5-IQR | K58: 0
A59: E1_A06 | B59: How many outliers does the MonthlyIncome variable contain, based on the 1.5 IQR rule? Answer with the number only. | C59: gemini-3.6-flash | D59: 3 | E59: ok | F59: 56 | G59: 56 | H59: 114 | I59: =ABS(G59-H59)/ABS(H59) -> 0.50877193 | J59: Anzahl nach exakt 1,5-IQR | K59: 0
A60: E1_A06 | B60: How many outliers does the MonthlyIncome variable contain, based on the 1.5 IQR rule? Answer with the number only. | C60: gemini-3.6-flash | D60: 4 | E60: ok | F60: To determine the number of outliers in the `MonthlyIncome` column using the 1.5 × IQR rule, we follow these steps: 1. **Calculate Quartiles:** * **Q1 (25th percentile):** $2,858$ * **Q3 (75th percentile):** $8,377$ 2. **Calculate Interquartile Range (IQR):** * $\text{IQR} = Q3 - Q1 = 8,377 - 2,858 = 5,519$ 3. **Determine Outlier Thresholds:** * **Lower Bound:** $Q1 - 1.5 \times \text{IQR} = 2,858 - 1.5 \times 5,519 = -5,420.5$ * **Upper Bound:** $Q3 + 1.5 \times \text{IQR} = 8,377 + 1.5 \times 5,519 = 16,655.5$ 4. **Identify Outliers:** * Any data point with `MonthlyIncom … | G60: 33 | H60: 114 | I60: =ABS(G60-H60)/ABS(H60) -> 0.71052632 | J60: Anzahl nach exakt 1,5-IQR | K60: 0
A61: E1_A06 | B61: How many outliers does the MonthlyIncome variable contain, based on the 1.5 IQR rule? Answer with the number only. | C61: gemini-3.6-flash | D61: 5 | E61: ABGESCHNITTEN | F61: To find the number of outliers in the `MonthlyIncome` column based on the 1.5 IQR rule, we calculate the First Quartile ($Q_1$), Third Quartile ($Q_3$), and Interquartile Range ($IQR$). 1. **Calculate Quartiles:** - **Total records ($N$):** 500 - **$Q_1$ (25th percentile):** $2,886$ - **$Q_3$ (75th percentile):** $8,380$ - **$IQR = Q_3 - Q_1$:** $8,380 - 2,886 = 5,494$ 2. **Determine Outlier Thresholds:** - **Upper Bound:** $Q_3 + 1.5 \times IQR = 8,380 + 1.5(5,494) = 16,621$ - **Lower Bound:** $Q_1 - 1.5 \times IQR = 2,886 - 1.5(5,494) = -5,355$ 3. **Count Outliers:** … | G61: kein Endwert | H61: 114 | I61: 100 | J61: Anzahl nach exakt 1,5-IQR | K61: 0
A62: E1_A07 | B62: What is the average distance from home (DistanceFromHome)? Answer with the number only. | C62: gpt-5.6-luna | D62: 1 | E62: ok | F62: 9.1925170068 | G62: 9.192517 | H62: 9.19 | I62: =ABS(G62-H62)/ABS(H62) -> 0.0002738854 | J62: numerischer Referenzwert | K62: 2
A63: E1_A07 | B63: What is the average distance from home (DistanceFromHome)? Answer with the number only. | C63: gpt-5.6-luna | D63: 2 | E63: ok | F63: 9.1925170068 | G63: 9.192517 | H63: 9.19 | I63: =ABS(G63-H63)/ABS(H63) -> 0.0002738854 | J63: numerischer Referenzwert | K63: 2
A64: E1_A07 | B64: What is the average distance from home (DistanceFromHome)? Answer with the number only. | C64: gpt-5.6-luna | D64: 3 | E64: ok | F64: 9.19251700680272 | G64: 9.192517 | H64: 9.19 | I64: =ABS(G64-H64)/ABS(H64) -> 0.0002738854 | J64: numerischer Referenzwert | K64: 2
A65: E1_A07 | B65: What is the average distance from home (DistanceFromHome)? Answer with the number only. | C65: gpt-5.6-luna | D65: 4 | E65: ok | F65: 9.1925170068 | G65: 9.192517 | H65: 9.19 | I65: =ABS(G65-H65)/ABS(H65) -> 0.0002738854 | J65: numerischer Referenzwert | K65: 2
A66: E1_A07 | B66: What is the average distance from home (DistanceFromHome)? Answer with the number only. | C66: gpt-5.6-luna | D66: 5 | E66: ok | F66: 9.1925170068 | G66: 9.192517 | H66: 9.19 | I66: =ABS(G66-H66)/ABS(H66) -> 0.0002738854 | J66: numerischer Referenzwert | K66: 2
A67: E1_A07 | B67: What is the average distance from home (DistanceFromHome)? Answer with the number only. | C67: gemini-3.6-flash | D67: 1 | E67: ok | F67: 9.28 | G67: 9.28 | H67: 9.19 | I67: =ABS(G67-H67)/ABS(H67) -> 0.0097932535 | J67: numerischer Referenzwert | K67: 2
A68: E1_A07 | B68: What is the average distance from home (DistanceFromHome)? Answer with the number only. | C68: gemini-3.6-flash | D68: 2 | E68: ABGESCHNITTEN | F68: 23 48: 19 49: 5 50: 8 Sum = 4+2+25+8+1+12+23+19+5+8 = 107 Rows 51-60: 51: 1 52: 5 53: 1 54: 11 55: 23 56: 1 57: 18 58: 23 59: 7 60: 1 Sum = 1+5+1+11+23+1+18+23+7+1 = 91 Rows 61-70: 61: 1 62: 29 63: 7 64: 25 65: 8 66: 8 67: 11 68: 7 69: 1 70: 9 Sum = 1+29+7+25+8+8+11+7+1+9 = 106 Rows 71-80: 71: 1 72: 2 73: 1 74: 1 75: 6 76: 6 77: 7 78: 6 | G68: 9 | H68: 9.19 | I68: =ABS(G68-H68)/ABS(H68) -> 0.020674646 | J68: numerischer Referenzwert | K68: 1
A69: E1_A07 | B69: What is the average distance from home (DistanceFromHome)? Answer with the number only. | C69: gemini-3.6-flash | D69: 3 | E69: ok | F69: To find the average distance from home (`DistanceFromHome`) for the employees in this dataset, we sum the values in the `DistanceFromHome` column and divide by the total number of employees (rows). - **Total sum of `DistanceFromHome`**: 3,678 - **Total number of employees**: 400 - **Average**: 3,678 / 400 = 9.195 9.195 | G69: 9.195 | H69: 9.19 | I69: =ABS(G69-H69)/ABS(H69) -> 0.00054406964 | J69: numerischer Referenzwert | K69: 2
A70: E1_A07 | B70: What is the average distance from home (DistanceFromHome)? Answer with the number only. | C70: gemini-3.6-flash | D70: 4 | E70: ok | F70: To find the average distance from home (`DistanceFromHome`) for the provided dataset, we sum the `DistanceFromHome` values for all 500 employees and divide by the total number of employees (500). - **Sum:** 4,603 - **Count:** 500 - **Average:** 4,603 / 500 = 9.206 9.206 | G70: 9.206 | H70: 9.19 | I70: =ABS(G70-H70)/ABS(H70) -> 0.0017410229 | J70: numerischer Referenzwert | K70: 2
A71: E1_A07 | B71: What is the average distance from home (DistanceFromHome)? Answer with the number only. | C71: gemini-3.6-flash | D71: 5 | E71: ok | F71: 9.192517006802721 | G71: 9.192517 | H71: 9.19 | I71: =ABS(G71-H71)/ABS(H71) -> 0.0002738854 | J71: numerischer Referenzwert | K71: 2
A72: E1_A08 | B72: Which department (Department) has the highest attrition rate? Name the department. | C72: gpt-5.6-luna | D72: 1 | E72: ok | F72: Sales has the highest attrition rate. | H72: Sales: 0.2063; Human Resources: 0.1905; Research & Development: 0.1384 | I72: OK | J72: richtige Abteilung | K72: 2
A73: E1_A08 | B73: Which department (Department) has the highest attrition rate? Name the department. | C73: gpt-5.6-luna | D73: 2 | E73: ok | F73: **Sales** has the highest attrition rate. | H73: Sales: 0.2063; Human Resources: 0.1905; Research & Development: 0.1384 | I73: OK | J73: richtige Abteilung | K73: 2
A74: E1_A08 | B74: Which department (Department) has the highest attrition rate? Name the department. | C74: gpt-5.6-luna | D74: 3 | E74: ok | F74: Sales has the highest attrition rate. | H74: Sales: 0.2063; Human Resources: 0.1905; Research & Development: 0.1384 | I74: OK | J74: richtige Abteilung | K74: 2
A75: E1_A08 | B75: Which department (Department) has the highest attrition rate? Name the department. | C75: gpt-5.6-luna | D75: 4 | E75: ok | F75: Sales. | H75: Sales: 0.2063; Human Resources: 0.1905; Research & Development: 0.1384 | I75: OK | J75: richtige Abteilung | K75: 2
A76: E1_A08 | B76: Which department (Department) has the highest attrition rate? Name the department. | C76: gpt-5.6-luna | D76: 5 | E76: ok | F76: Sales. | H76: Sales: 0.2063; Human Resources: 0.1905; Research & Development: 0.1384 | I76: OK | J76: richtige Abteilung | K76: 2
A77: E1_A08 | B77: Which department (Department) has the highest attrition rate? Name the department. | C77: gemini-3.6-flash | D77: 1 | E77: ok | F77: To find the department with the highest attrition rate, we calculate the proportion of employees who left (`Attrition = Yes`) relative to the total number of employees in each department: 1. **Sales:** * Total Employees: 179 * Attrition Count (`Yes`): 37 * **Attrition Rate: ~20.67%** 2. **Human Resources:** * Total Employees: 27 * Attrition Count (`Yes`): 5 * **Attrition Rate: ~18.52%** 3. **Research & Development:** * Total Employees: 294 * Attrition Count (`Yes`): 41 * **Attrition Rate: ~13.95%** The department with the highest attrition rate is **Sales**. | H77: Sales: 0.2063; Human Resources: 0.1905; Research & Development: 0.1384 | I77: OK | J77: richtige Abteilung | K77: 2
A78: E1_A08 | B78: Which department (Department) has the highest attrition rate? Name the department. | C78: gemini-3.6-flash | D78: 2 | E78: ABGESCHNITTEN | F78: Human Resources... (No) Line 309: 50,No,Travel_Frequently,1246,Human Resources... (No) Line 310: 44,No,Travel_Rarely,1112,Human Resources... (No) Line 316: 42,No,Non-Travel,179,Human Resources... (No) Line 321: 38,No,Travel_Rarely,433,Human Resources... (No) Line 328: 33,No,Travel_Rarely,147,Human Resources... (No) Line 332: 34,No,Travel_Frequently,648,Human Resources... (No) Line 336: 35,No,Travel_Rarely,528,Human Resources... (No) Line 352: 42,No,Travel_Rarely,1147,Human Resources... (No) Line 353: 29,No,Travel_Rarely,332,Human Resources... (No) Line 358: 46,No,Travel_Rarely,991,Human Resour … | H78: Sales: 0.2063; Human Resources: 0.1905; Research & Development: 0.1384 | I78: ? | J78: richtige Abteilung | K78: 0
A79: E1_A08 | B79: Which department (Department) has the highest attrition rate? Name the department. | C79: gemini-3.6-flash | D79: 3 | E79: ok | F79: To determine which department has the highest attrition rate in this dataset (the IBM HR Employee Attrition dataset), we calculate the attrition rate for each department as: $$\text{Attrition Rate} = \frac{\text{Number of employees who left (Attrition = Yes)}}{\text{Total number of employees in the department}} \times 100\%$$ ### **Department Breakdown:** 1. **Sales:** * **Total Employees:** 446 * **Attrition (Yes):** 92 * **Attrition Rate:** $\approx \mathbf{20.63\%}$ 2. **Human Resources:** * **Total Employees:** 63 * **Attrition (Yes):** 12 * **Attrition Rate:** $\appro … | H79: Sales: 0.2063; Human Resources: 0.1905; Research & Development: 0.1384 | I79: OK | J79: richtige Abteilung | K79: 2
A80: E1_A08 | B80: Which department (Department) has the highest attrition rate? Name the department. | C80: gemini-3.6-flash | D80: 4 | E80: ok | F80: To determine the department with the highest attrition rate, we calculate the percentage of employees who left (`Attrition = "Yes"`) within each department: 1. **Human Resources (HR):** - Total Employees: 36 - Attrition ("Yes"): 9 - **Attrition Rate:** $9 / 36 = 25.0\%$ 2. **Sales:** - Total Employees: 138 - Attrition ("Yes"): 29 - **Attrition Rate:** $29 / 138 \approx 21.01\%$ 3. **Research & Development (R&D):** - Total Employees: 226 - Attrition ("Yes"): 27 - **Attrition Rate:** $27 / 226 \approx 11.95\%$ ### **Answer:** **Human Resources** | H80: Sales: 0.2063; Human Resources: 0.1905; Research & Development: 0.1384 | I80: Wrong | J80: richtige Abteilung | K80: 0
A81: E1_A08 | B81: Which department (Department) has the highest attrition rate? Name the department. | C81: gemini-3.6-flash | D81: 5 | E81: ok | F81: To determine which department has the highest attrition rate, we calculate the number of employees who left (`Attrition = Yes`) relative to the total number of employees in each department: 1. **Sales**: - Total Employees: 446 - Attritions (`Yes`): 92 - **Attrition Rate**: **~20.63%** 2. **Human Resources**: - Total Employees: 63 - Attritions (`Yes`): 12 - **Attrition Rate**: **~19.05%** 3. **Research & Development**: - Total Employees: 961 - Attritions (`Yes`): 133 - **Attrition Rate**: **~13.84%** ### Answer: The department with the highest attrition rate is ** … | H81: Sales: 0.2063; Human Resources: 0.1905; Research & Development: 0.1384 | I81: OK | J81: richtige Abteilung | K81: 2
A82: E1_A09 | B82: Do employees who work overtime (OverTime) have a higher or lower attrition rate than those who do not? State the direction. | C82: gpt-5.6-luna | D82: 1 | E82: ok | F82: Employees who work overtime have a **higher attrition rate** than employees who do not work overtime. | H82: Yes: 0.3053; No: 0.1044 | I82: OK | J82: "Yes" höher | K82: 2
A83: E1_A09 | B83: Do employees who work overtime (OverTime) have a higher or lower attrition rate than those who do not? State the direction. | C83: gpt-5.6-luna | D83: 2 | E83: ok | F83: Employees who work overtime have a **higher attrition rate** than those who do not work overtime. | H83: Yes: 0.3053; No: 0.1044 | I83: OK | J83: "Yes" höher | K83: 2
...

Sheet Auswertung A
A1: Frage-ID | B1: gpt-5.6-luna | C1: gemini-3.6-flash | D1: Luna SD | E1: Gemini SD
A2: E1_A01 | B2: =AVERAGEIFS('A faktisch'!$K:$K,'A faktisch'!$A:$A,$A2,'A faktisch'!$C:$C,B$1) -> 2 | C2: =AVERAGEIFS('A faktisch'!$K:$K,'A faktisch'!$A:$A,$A2,'A faktisch'!$C:$C,C$1) -> 0.4 | D2: =IFERROR(__xludf.DUMMYFUNCTION("STDEV.S(FILTER('A faktisch'!$K:$K,'A faktisch'!$A:$A=$A2,'A faktisch'!$C:$C=""gpt-5.6-luna""))"),0.0) -> 0 | E2: =IFERROR(__xludf.DUMMYFUNCTION("STDEV.S(FILTER('A faktisch'!$K:$K,'A faktisch'!$A:$A=$A2,'A faktisch'!$C:$C=""gemini-3.6-flash""))"),0.8944271909999159) -> 0.89442719
A3: E1_A02 | B3: =AVERAGEIFS('A faktisch'!$K:$K,'A faktisch'!$A:$A,$A3,'A faktisch'!$C:$C,B$1) -> 2 | C3: =AVERAGEIFS('A faktisch'!$K:$K,'A faktisch'!$A:$A,$A3,'A faktisch'!$C:$C,C$1) -> 2 | D3: =IFERROR(__xludf.DUMMYFUNCTION("STDEV.S(FILTER('A faktisch'!$K:$K,'A faktisch'!$A:$A=$A3,'A faktisch'!$C:$C=""gpt-5.6-luna""))"),0.0) -> 0 | E3: =IFERROR(__xludf.DUMMYFUNCTION("STDEV.S(FILTER('A faktisch'!$K:$K,'A faktisch'!$A:$A=$A3,'A faktisch'!$C:$C=""gemini-3.6-flash""))"),0.0) -> 0
A4: E1_A03 | B4: =AVERAGEIFS('A faktisch'!$K:$K,'A faktisch'!$A:$A,$A4,'A faktisch'!$C:$C,B$1) -> 2 | C4: =AVERAGEIFS('A faktisch'!$K:$K,'A faktisch'!$A:$A,$A4,'A faktisch'!$C:$C,C$1) -> 1.6 | D4: =IFERROR(__xludf.DUMMYFUNCTION("STDEV.S(FILTER('A faktisch'!$K:$K,'A faktisch'!$A:$A=$A4,'A faktisch'!$C:$C=""gpt-5.6-luna""))"),0.0) -> 0 | E4: =IFERROR(__xludf.DUMMYFUNCTION("STDEV.S(FILTER('A faktisch'!$K:$K,'A faktisch'!$A:$A=$A4,'A faktisch'!$C:$C=""gemini-3.6-flash""))"),0.8944271909999159) -> 0.89442719
A5: E1_A04 | B5: =AVERAGEIFS('A faktisch'!$K:$K,'A faktisch'!$A:$A,$A5,'A faktisch'!$C:$C,B$1) -> 2 | C5: =AVERAGEIFS('A faktisch'!$K:$K,'A faktisch'!$A:$A,$A5,'A faktisch'!$C:$C,C$1) -> 0.8 | D5: =IFERROR(__xludf.DUMMYFUNCTION("STDEV.S(FILTER('A faktisch'!$K:$K,'A faktisch'!$A:$A=$A5,'A faktisch'!$C:$C=""gpt-5.6-luna""))"),0.0) -> 0 | E5: =IFERROR(__xludf.DUMMYFUNCTION("STDEV.S(FILTER('A faktisch'!$K:$K,'A faktisch'!$A:$A=$A5,'A faktisch'!$C:$C=""gemini-3.6-flash""))"),0.4472135954999579) -> 0.4472136
A6: E1_A05 | B6: =AVERAGEIFS('A faktisch'!$K:$K,'A faktisch'!$A:$A,$A6,'A faktisch'!$C:$C,B$1) -> 2 | C6: =AVERAGEIFS('A faktisch'!$K:$K,'A faktisch'!$A:$A,$A6,'A faktisch'!$C:$C,C$1) -> 2 | D6: =IFERROR(__xludf.DUMMYFUNCTION("STDEV.S(FILTER('A faktisch'!$K:$K,'A faktisch'!$A:$A=$A6,'A faktisch'!$C:$C=""gpt-5.6-luna""))"),0.0) -> 0 | E6: =IFERROR(__xludf.DUMMYFUNCTION("STDEV.S(FILTER('A faktisch'!$K:$K,'A faktisch'!$A:$A=$A6,'A faktisch'!$C:$C=""gemini-3.6-flash""))"),0.0) -> 0
A7: E1_A06 | B7: =AVERAGEIFS('A faktisch'!$K:$K,'A faktisch'!$A:$A,$A7,'A faktisch'!$C:$C,B$1) -> 1.6 | C7: =AVERAGEIFS('A faktisch'!$K:$K,'A faktisch'!$A:$A,$A7,'A faktisch'!$C:$C,C$1) -> 0 | D7: =IFERROR(__xludf.DUMMYFUNCTION("STDEV.S(FILTER('A faktisch'!$K:$K,'A faktisch'!$A:$A=$A7,'A faktisch'!$C:$C=""gpt-5.6-luna""))"),0.8944271909999159) -> 0.89442719 | E7: =IFERROR(__xludf.DUMMYFUNCTION("STDEV.S(FILTER('A faktisch'!$K:$K,'A faktisch'!$A:$A=$A7,'A faktisch'!$C:$C=""gemini-3.6-flash""))"),0.0) -> 0
A8: E1_A07 | B8: =AVERAGEIFS('A faktisch'!$K:$K,'A faktisch'!$A:$A,$A8,'A faktisch'!$C:$C,B$1) -> 2 | C8: =AVERAGEIFS('A faktisch'!$K:$K,'A faktisch'!$A:$A,$A8,'A faktisch'!$C:$C,C$1) -> 1.8 | D8: =IFERROR(__xludf.DUMMYFUNCTION("STDEV.S(FILTER('A faktisch'!$K:$K,'A faktisch'!$A:$A=$A8,'A faktisch'!$C:$C=""gpt-5.6-luna""))"),0.0) -> 0 | E8: =IFERROR(__xludf.DUMMYFUNCTION("STDEV.S(FILTER('A faktisch'!$K:$K,'A faktisch'!$A:$A=$A8,'A faktisch'!$C:$C=""gemini-3.6-flash""))"),0.4472135954999579) -> 0.4472136
A9: E1_A08 | B9: =AVERAGEIFS('A faktisch'!$K:$K,'A faktisch'!$A:$A,$A9,'A faktisch'!$C:$C,B$1) -> 2 | C9: =AVERAGEIFS('A faktisch'!$K:$K,'A faktisch'!$A:$A,$A9,'A faktisch'!$C:$C,C$1) -> 1.2 | D9: =IFERROR(__xludf.DUMMYFUNCTION("STDEV.S(FILTER('A faktisch'!$K:$K,'A faktisch'!$A:$A=$A9,'A faktisch'!$C:$C=""gpt-5.6-luna""))"),0.0) -> 0 | E9: =IFERROR(__xludf.DUMMYFUNCTION("STDEV.S(FILTER('A faktisch'!$K:$K,'A faktisch'!$A:$A=$A9,'A faktisch'!$C:$C=""gemini-3.6-flash""))"),1.0954451150103321) -> 1.0954451
A10: E1_A09 | B10: =AVERAGEIFS('A faktisch'!$K:$K,'A faktisch'!$A:$A,$A10,'A faktisch'!$C:$C,B$1) -> 2 | C10: =AVERAGEIFS('A faktisch'!$K:$K,'A faktisch'!$A:$A,$A10,'A faktisch'!$C:$C,C$1) -> 2 | D10: =IFERROR(__xludf.DUMMYFUNCTION("STDEV.S(FILTER('A faktisch'!$K:$K,'A faktisch'!$A:$A=$A10,'A faktisch'!$C:$C=""gpt-5.6-luna""))"),0.0) -> 0 | E10: =IFERROR(__xludf.DUMMYFUNCTION("STDEV.S(FILTER('A faktisch'!$K:$K,'A faktisch'!$A:$A=$A10,'A faktisch'!$C:$C=""gemini-3.6-flash""))"),0.0) -> 0
A11: E1_A10 | B11: =AVERAGEIFS('A faktisch'!$K:$K,'A faktisch'!$A:$A,$A11,'A faktisch'!$C:$C,B$1) -> 2 | C11: =AVERAGEIFS('A faktisch'!$K:$K,'A faktisch'!$A:$A,$A11,'A faktisch'!$C:$C,C$1) -> 2 | D11: 0 | E11: 0
A12: Gesamtmittelwert | B12: =AVERAGE(B2:B11) -> 1.96 | C12: =AVERAGE(C2:C11) -> 1.38 | D12: 0 | E12: 0

Sheet B interpretativ
A1: Frage-ID | B1: Frage | C1: Modell | D1: It. | E1: Status | F1: Antwort | G1: Referenz (Soll-Inhalt) | H1: Punkte 0-2 | I1: Notiz
A2: E1_B01 | B2: Which factors are most strongly associated with employees leaving the company (Attrition)? Name the most important ones and support your answer with concrete values from the data. | C2: gemini-3.6-flash | D2: 1 | E2: ok | F2: Based on an analysis of the provided dataset, the most significant factors strongly associated with employee attrition (**Attrition = Yes**) are:\n\n---\n\n### 1. **OverTime**\n* **Finding:** Working overtime is one of the single strongest predictors of employee departure.\n* **Evidence from Data:** \n * A disproportionately large percentage of employees who left the company worked overtime (`OverTime = Yes`).\n * Examples of employees leaving with `OverTime = Yes`: EmployeeNumber 1 (Age 41), EmployeeNumber 4 (Age 37), EmployeeNumber 19 (Age 28), EmployeeNumber 64 (Age 48), EmployeeNumber 65 (Age 28), EmployeeNumber 137 (Age 20), EmployeeNumber 142 (Age 25), EmployeeNumber 147 (Age 34), and many others.\n * Employees who do not work overtime (`OverTime = No`) stay with the company at a significantly higher rate.\n\n---\n\n### 2. **Marital Status & Age**\n* **Finding:** Younger and single employees are significantly more likely to leave.\n* **Evidence from Data:**\n * **Single Employees:** Single employees represent a major portion of all attrition cases (e.g., EmployeeNumbers 1, 4, 19, 27, 31, 33, 55, 64, 65, 137, 142, 147, 167, 235, 243, etc.).\n * **Younger Age:** Many departures occur among employees aged under 30 (e.g., ages 18, 19, 20, 21, 24, 25, 26, 28, 29). For instance:\n * EmployeeNumber 167 (Age 19, Single, Attrition = Yes)\n * EmployeeNumber 235 (Age 19, Single, Attrition = Yes)\n * EmployeeNumber 243 (Age 19, Single, Attrition = Yes)\n * EmployeeNumber 137 (Age 20, Single, Attrition = Yes)\n\n---\n\n### 3. **Stock Option Level**\n* **Finding:** Employees with no stock options (`StockOptionLevel = 0`) are far more likely to leave compared to those with equity incentives (levels 1–3).\n* **Evidence from Data:**\n * Overwhelmingly, employees with `Attrition = Yes` have `StockOptionLevel = 0` (e.g., EmployeeNumbers 1, 4, 19, 27, 31, 33, 47, 55, 64, 65, 137, 142, 147, 167, 175, 179, etc.).\n * Having at least `StockOptionLevel = 1` or `2` serves as a strong retention mechanism.\n\n---\n\n### 4. **Business Travel Frequency**\n* **Finding:** Frequent travel correlates with higher turnover rates.\n* **Evidence from Data:**\n * While `Travel_Rarely` is the majority travel type overall, employees categorized as `Travel_Frequently` have a much higher rate of attrition relative to their total headcount.\n * Examples of frequent travelers who left include EmployeeNumbers 33 (Age 32), 137 (Age 20), 147 (Age 34), 179 (Age 51), 235 (Age 19), 299 (Age 30), 342 (Age 37), and 355 (Age 31).\n\n---\n\n### 5. **Job Level & Monthly Income**\n* **Finding:** Entry-level position holders (Job Level 1) with lower monthly compensation exhibit higher turnover.\n* **Evidence from Data:**\n * The vast majority of attrition cases occur at **JobLevel = 1** or **2** with lower `MonthlyIncome` (e.g., $1,009 to $3,500/month).\n * Examples:\n * EmployeeNumber 167: Monthly Income $1,675 (Level 1, Attrition = Yes)\n * EmployeeNumber 235: Monthly Income $2,325 (Level 1, Attrition = Yes)\n * EmployeeNumber 243: Monthly Income $1,102 (Level 1, Attrition = Yes)\n * EmployeeNumber 19: Monthly Income $2,028 (Level 1, Attrition = Yes)\n\n---\n\n### **Summary Risk Profile of a Departing Employee**\nAn employee with the highest likelihood of leaving typically matches this profile:\n* **Works OverTime:** Yes\n* **Marital Status:** Single\n* **Stock Option Level:** 0\n* **Age:** Under 30\n* **Job Level / Income:** Level 1, low monthly income | G2: {"wert": {"OverTime_num": 0.2461, "TotalWorkingYears": -0.1711, "JobLevel": -0.1691, "YearsInCurrentRole": -0.1605, "MonthlyIncome": -0.1598}, "typ": "rangfolge", "toleranz": "richtung", "quelle": "Pearson corr mit Attrition_num, Top 5 nach Betrag"} | H2: 1 | I2: Grundrichtung plausibel aber statt der stärksten Zusammenhänge werden u.a. MartialStatus, StockoptionLevel und Business Travel hervorgehoben
A3: E1_B01 | B3: Which factors are most strongly associated with employees leaving the company (Attrition)? Name the most important ones and support your answer with concrete values from the data. | C3: gemini-3.6-flash | D3: 2 | E3: ABGESCHNITTEN | F3: Based on an exploratory data analysis of the provided dataset, the following key factors are most strongly associated with employee attrition (**`Attrition = Yes`**):\n\n---\n\n### 1. OverTime Work (Strongest Single Predictor)\n* **Finding:** Working overtime is heavily linked to higher employee turnover.\n* **Data Evidence:**\n * Employees who work overtime (**`OverTime = Yes`**) have an attrition rate of approximately **30–32%**, compared to only **~10–11%** for those who do not work overtime (**`OverTime = No`**).\n * Out of all employees who left the company, **nearly half worked overtime**, even though overtime workers represent a much smaller minority of the overall workforce.\n\n---\n\n### 2. Age and Total Working Years (Younger / Early-Career Employees)\n* **Finding:** Younger employees and those early in their careers are significantly more likely to leave.\n* **Data Evidence:**\n * Employees **under 30 years old** experience an attrition rate of nearly **25–30%**, whereas employees **over 40 years old** have an attrition rate below **10%**.\n * Among very young employees (ages 18–22), attrition is particularly severe (e.g., Employee Nos. 167, 235, 243, 405, 478, 701, 922, 1156, 1279, 1624 all left).\n * **TotalWorkingYears:** Employees leaving the company have a much lower average total working years (around **4–6 years**) compared to those staying (around **11+ years**).\n\n---\n\n### 3. Stock Option Level\n* **Finding:** Lack of stock options significantly increases turnover risk.\n* **Data Evidence:**\n * Employees with **`StockOptionLevel = 0`** account for over **60% of all attritions**.\n * Employees with **`StockOptionLevel = 1` or `2`** show significantly lower attrition rates (~7–10%), indicating that equity grants serve as an effective retention mechanism.\n\n---\n\n### 4. Monthly Income & Job Level\n* **Finding:** Lower job levels and lower monthly salaries correlate strongly with higher attrition.\n* **Data Evidence:**\n * **Job Level 1** employees (entry-level) have the highest attrition rate.\n * Employees who left had a median Monthly Income around **$2,500 – $3,500**, whereas retained employees had a median Monthly Income well above **$5,000**.\n * Senior roles like **Manager** and **Research Director** (Job Levels 4 & 5 with monthly incomes > $12,000) show near-zero attrition in this sample.\n\n---\n\n### 5. Business Travel Frequency\n* **Finding:** Frequent business travel drives higher turnover.\n* **Data Evidence:**\n * Employees in the **`Travel_Frequently`** category have an attrition rate of **~24%**, compared to **~13%** for **`Travel_Rarely`** and **~8%** for **`Non-Travel`**.\n\n---\n\n### 6. Job Role Disparities\n* **Finding:** Attrition is heavily concentrated in specific operational and frontline sales roles.\n* **Data Evidence:**\n * Roles with the highest attrition count and rate:\n 1. **Sales Representative** (high turnover due to lower base income and high travel)\n 2. **Laboratory Technician**\n 3. **Research Scientist**\n * In contrast, **Healthcare Representatives**, **Manufacturing Directors**, and **Managers** show very low attrition.\n\n---\n\n### Summary Checklist for Attrition Risk Profile\nAn employee at the **highest risk of leaving** typically matches this profile | G3: {"wert": {"OverTime_num": 0.2461, "TotalWorkingYears": -0.1711, "JobLevel": -0.1691, "YearsInCurrentRole": -0.1605, "MonthlyIncome": -0.1598}, "typ": "rangfolge", "toleranz": "richtung", "quelle": "Pearson corr mit Attrition_num, Top 5 nach Betrag"} | H3: 2 | I3: Zentrale Zusammenhänge korrekt identifiziert und überwiegend quantitativ belegt; einzelne kausale Formulierungen zu stark
A4: E1_B01 | B4: Which factors are most strongly associated with employees leaving the company (Attrition)? Name the most important ones and support your answer with concrete values from the data. | C4: gemini-3.6-flash | D4: 3 | E4: ok | F4: Based on an exploratory analysis of the provided dataset, the most important factors strongly associated with employee **Attrition ("Yes")** are: --- ### 1. **OverTime (Workload and Burnout)** * **Observation:** Working overtime is one of the single strongest predictors of employee departure. * **Data Evidence:** * A very large proportion of employees who left the company worked overtime (e.g., Employee #1, #4, #19, #33, #64, #65, #137, #142, #147, #161, #163). * Employees without overtime show significantly lower attrition rates and higher overall retention across almost all job roles and departments. --- ### 2. **Low Monthly Income and Entry Job Level (JobLevel = 1)** * **Observation:** Attrition is heavily concentrated among lower-earning employees and entry-level staff (Job Lev … | G4: {"wert": {"OverTime_num": 0.2461, "TotalWorkingYears": -0.1711, "JobLevel": -0.1691, "YearsInCurrentRole": -0.1605, "MonthlyIncome": -0.1598}, "typ": "rangfolge", "toleranz": "richtung", "quelle": "Pearson corr mit Attrition_num, Top 5 nach Betrag"} | H4: 1 | I4: Relevante Faktoren erkannt, aber überwiegend Einzelbeispiele statt aggregierter Evidenz und teilweise kausale Interpretation.
A5: E1_B01 | B5: Which factors are most strongly associated with employees leaving the company (Attrition)? Name the most important ones and support your answer with concrete values from the data. | C5: gemini-3.6-flash | D5: 4 | E5: ok | F5: Based on an exploratory data analysis of the provided dataset, the most critical factors strongly associated with employee **Attrition ("Yes")** are **OverTime**, **Monthly Income & Job Level**, **Age & Total Working Years**, **Stock Option Level & Marital Status**, and **Tenure with Company/Manager**. --- ### 1. OverTime Work (Workload Stress) * **Finding**: Working overtime is the single strongest indicator of employee attrition in this dataset. * **Data Evidence**: * A majority of employees who left the company (`Attrition = Yes`) were working overtime (`OverTime = Yes`). * Examples from the data: * Employee #1 (Age 41, Sales Executive): **OverTime = Yes** $\rightarrow$ Attrition = **Yes** * Employee #4 (Age 37, Lab Technician, Income $2,090): **OverTime = Yes** $\rightar … | G5: {"wert": {"OverTime_num": 0.2461, "TotalWorkingYears": -0.1711, "JobLevel": -0.1691, "YearsInCurrentRole": -0.1605, "MonthlyIncome": -0.1598}, "typ": "rangfolge", "toleranz": "richtung", "quelle": "Pearson corr mit Attrition_num, Top 5 nach Betrag"} | H5: 1 | I5: Relevante Faktoren erkannt, aber überwiegend Einzelbeispiele; zusätzlich unbelegte kausale Erklärung bei Marital Status („due to ... higher mobility“).
A6: E1_B01 | B6: Which factors are most strongly associated with employees leaving the company (Attrition)? Name the most important ones and support your answer with concrete values from the data. | C6: gemini-3.6-flash | D6: 5 | E6: ok | F6: Based on an exploratory data analysis of the provided dataset (500 employee records, with an overall attrition rate of **15.8%** / 79 left vs. 421 stayed), the following factors are most strongly associated with employee attrition: --- ### 1. OverTime (Work Overtime) **OverTime is the single strongest binary predictor of attrition.** * **OverTime = Yes:** **29.1%** attrition rate (41 out of 141 employees working overtime left). * **OverTime = No:** **10.6%** attrition rate (38 out of 359 employees not working overtime left). * **Key Finding:** Employees who work overtime are nearly **2.75x more likely** to leave the company. --- ### 2. Monthly Income & Job Level **Lower compensation and entry-level positions show significantly higher attrition.** * **Average Monthly Income:** * **Att … | G6: {"wert": {"OverTime_num": 0.2461, "TotalWorkingYears": -0.1711, "JobLevel": -0.1691, "YearsInCurrentRole": -0.1605, "MonthlyIncome": -0.1598}, "typ": "rangfolge", "toleranz": "richtung", "quelle": "Pearson corr mit Attrition_num, Top 5 nach Betrag"} | H6: 0 | I6: Analyse basiert fälschlicherweise auf 500 statt 1.470 Beobachtungen; dadurch stammen die konkreten Kennzahlen nicht aus dem vollständigen Datensatz.
A7: E1_B01 | C7: gpt-5.6-luna | D7: 1 | E7: ok | F7: The strongest associations with **Attrition = Yes** in this dataset are: | Factor | Evidence from the data | |---|---| | **Overtime** | Employees working overtime leave at about **30.5%** (**127 of 416**) versus about **10.4%** (**110 of 1,054**) among employees not working overtime. This is the clearest association—roughly a threefold difference. | | **Stock-option level** | Attrition is highest for employees with **StockOptionLevel = 0**: about **24.4%** (**154 of 631**). It is much lower for level 1, about **9.4%** (**56 of 596**), and level 2, about **7.6%** (**12 of 158**). | | **Job level / seniority and compensation** | **JobLevel = 1** employees have attrition of roughly **26%** (**143 of 543**), compared with approximately **10%** at JobLevel 2 and below **5%** at JobLevel 4. The … | G7: {"wert": {"OverTime_num": 0.2461, "TotalWorkingYears": -0.1711, "JobLevel": -0.1691, "YearsInCurrentRole": -0.1605, "MonthlyIncome": -0.1598}, "typ": "rangfolge", "toleranz": "richtung", "quelle": "Pearson corr mit Attrition_num, Top 5 nach Betrag"} | H7: 2
A8: E1_B01 | B8: Which factors are most strongly associated with employees leaving the company (Attrition)? Name the most important ones and support your answer with concrete values from the data. | C8: gpt-5.6-luna | D8: 2 | E8: ok | F8: The strongest associations with attrition in this dataset are: | Factor | Attrition pattern | |---|---| | **Overtime** | Employees working overtime: **127 of 416 left (30.5%)**. Employees not working overtime: **110 of 1,054 (10.4%)**. This is the clearest categorical difference—nearly **3× higher** attrition with overtime. | | **Job level / seniority** | Attrition is concentrated among lower job levels. **Job Level 1:** **143 of 543 (26.3%)** left; **Job Level 2:** **52 of 534 (9.7%)**; **Job Level 4:** **5 of 106 (4.7%)**. Lower-level employees therefore have substantially higher turnover. | | **Stock-option level** | Employees with no stock options had attrition of **154 of 631 (24.4%)**. This fell to **56 of 596 (9.4%)** for stock-option level 1 and **12 of 158 (7.6%)** for level 2. L … | G8: {"wert": {"OverTime_num": 0.2461, "TotalWorkingYears": -0.1711, "JobLevel": -0.1691, "YearsInCurrentRole": -0.1605, "MonthlyIncome": -0.1598}, "typ": "rangfolge", "toleranz": "richtung", "quelle": "Pearson corr mit Attrition_num, Top 5 nach Betrag"} | H8: 2
A9: E1_B01 | B9: Which factors are most strongly associated with employees leaving the company (Attrition)? Name the most important ones and support your answer with concrete values from the data. | C9: gpt-5.6-luna | D9: 3 | E9: ok | F9: Using the overall attrition rate as a baseline: - **237 of 1,470 employees left: 16.1%** The strongest associations in this dataset are: | Factor | Group | Attrition | Attrition rate | |---|---:|---:|---:| | **OverTime** | Yes | 127 / 416 | **30.5%** | | | No | 110 / 1,054 | 10.4% | | **Job level** | Level 1 | 143 / 543 | **26.3%** | | | Level 2 | 52 / 534 | 9.7% | | | Level 4 | 5 / 106 | 4.7% | | **Marital status** | Single | 120 / 470 | **25.5%** | | | Married | 84 / 673 | 12.5% | | | Divorced | 33 / 327 | 10.1% | | **Business travel** | Travel_Frequently | 69 / 277 | **24.9%** | | | Travel_Rarely | 156 / 1,043 | 15.0% | | | Non-Travel | 12 / 150 | 8.0% | | **Stock option level** | 0 | 154 / 631 | **24.4%** | | | 1 | 56 / 596 | 9.4% | | | 2 | 12 / 158 | 7.6% | | **Job role** … | G9: {"wert": {"OverTime_num": 0.2461, "TotalWorkingYears": -0.1711, "JobLevel": -0.1691, "YearsInCurrentRole": -0.1605, "MonthlyIncome": -0.1598}, "typ": "rangfolge", "toleranz": "richtung", "quelle": "Pearson corr mit Attrition_num, Top 5 nach Betrag"} | H9: 2
A10: E1_B01 | B10: Which factors are most strongly associated with employees leaving the company (Attrition)? Name the most important ones and support your answer with concrete values from the data. | C10: gpt-5.6-luna | D10: 4 | E10: ok | F10: The strongest associations with attrition are behavioral and job-related rather than demographic. The clearest patterns are: | Factor | Evidence from the data | |---|---| | **OverTime** | Employees working overtime leave at a much higher rate: **127 of 416 overtime employees (30.5%)** left, compared with **110 of 1,054 non-overtime employees (10.4%)**. This is the strongest single categorical relationship. | | **Job level / seniority** | Attrition is concentrated among junior employees: **143 of 543 Job Level 1 employees (26.3%)** left, versus **52 of 534 at Level 2 (9.7%)**, **32 of 218 at Level 3 (14.7%)**, and only **5 of 106 at Level 4 (4.7%)**. | | **Age and experience** | Younger and newer employees are more likely to leave. The data includes multiple very young leavers—for example, … | G10: {"wert": {"OverTime_num": 0.2461, "TotalWorkingYears": -0.1711, "JobLevel": -0.1691, "YearsInCurrentRole": -0.1605, "MonthlyIncome": -0.1598}, "typ": "rangfolge", "toleranz": "richtung", "quelle": "Pearson corr mit Attrition_num, Top 5 nach Betrag"} | H10: 2 | I10: Teilweise Überinterpretation (z. B. „Stock options likely represent a retention incentive“, „Longer commutes are associated with higher attrition“ ohne starke quantitative Belege).
A11: E1_B01 | B11: Which factors are most strongly associated with employees leaving the company (Attrition)? Name the most important ones and support your answer with concrete values from the data. | C11: gpt-5.6-luna | D11: 5 | E11: ok | F11: The dataset contains **1,470 employees**, of whom **237 left** (**16.1% overall attrition**). The strongest associations with attrition are: | Factor | Attrition pattern | Interpretation | |---|---:|---| | **OverTime** | **127 of 416 employees working overtime left (30.5%)**, versus **110 of 1,054 not working overtime (10.4%)** | Overtime employees were about **2.9 times as likely** to leave. This is the clearest categorical association. | | **Age / career stage** | Employees who left had mean age **33.6**, compared with **37.6** among those who stayed | Attrition is concentrated among younger employees, particularly early-career staff. | | **Job level and income** | Mean JobLevel was **1.64** for leavers versus **2.07** for non-leavers; mean MonthlyIncome was approximately **$4,787** ver … | G11: {"wert": {"OverTime_num": 0.2461, "TotalWorkingYears": -0.1711, "JobLevel": -0.1691, "YearsInCurrentRole": -0.1605, "MonthlyIncome": -0.1598}, "typ": "rangfolge", "toleranz": "richtung", "quelle": "Pearson corr mit Attrition_num, Top 5 nach Betrag"} | H11: 2
A12: E1_B02 | B12: Are there combinations of characteristics that occur together with a particularly high attrition rate? Describe the most notable combinations. | C12: gemini-3.6-flash | D12: 1 | E12: ok | F12: Based on an exploratory analysis of this HR dataset, several specific combinations of employee characteristics correlate with a **significantly higher rate of attrition**: --- ### 1. **OverTime = "Yes" + Low Job Level (Job Level 1) / Specific Roles** * **Notable Roles:** *Sales Representative* and *Laboratory Technician* * **Pattern:** Employees in entry-level positions (Job Level 1) who work **OverTime** exhibit the highest overall attrition rates in the dataset. * **Key Driver:** The combination of lower base pay, high workload/overtime demand, and lower job autonomy creates severe burnout and turnover risk. --- ### 2. **Marital Status = "Single" + OverTime = "Yes"** * **Pattern:** Single employees who work OverTime leave at a rate substantially higher than married or divorced emplo … | G12: {"wert": [{"wenn": ["OverTime_Yes", "YearsAtCompany_bin_niedrig"], "dann": "Attrition_Yes", "support": 0.051, "confidence": 0.431, "improvement": 0.1257, "lift": 2.6735}, {"wenn": ["Age_bin_niedrig", "MaritalStatus_Single"], "dann": "Attrition_Yes", "support": 0.051, "confidence": 0.3886, "improvement": 0.1333, "lift": 2.4103}, {"wenn": ["Age_bin_niedrig", "YearsAtCompany_bin_niedrig"], "dann": "A | H12: 1 | I12: zentrale Referenzkombination OverTime + niedrige Betriebszugehörigkeit nicht klar erkannt.
A13: E1_B02 | B13: Are there combinations of characteristics that occur together with a particularly high attrition rate? Describe the most notable combinations. | C13: gemini-3.6-flash | D13: 2 | E13: ok | F13: Based on exploratory data analysis of this dataset (IBM HR Analytics dataset), several distinct **combinations of characteristics** exhibit a particularly high rate of employee attrition (`Attrition = Yes`). The most notable high-attrition combinations include: --- ### 1. **OverTime = "Yes" + MaritalStatus = "Single"** * **Key Traits:** Employees working overtime who are single. * **Analysis:** Overtime is one of the strongest individual predictors of attrition. When combined with a single marital status, employees have fewer personal ties binding them to a location/schedule and greater mobility, leading to a significantly higher turnover rate compared to married or divorced peers working standard hours. --- ### 2. **JobLevel = 1 (Entry-Level) + OverTime = "Yes" + Low Tenure (`YearsA … | G13: {"wert": [{"wenn": ["OverTime_Yes", "YearsAtCompany_bin_niedrig"], "dann": "Attrition_Yes", "support": 0.051, "confidence": 0.431, "improvement": 0.1257, "lift": 2.6735}, {"wenn": ["Age_bin_niedrig", "MaritalStatus_Single"], "dann": "Attrition_Yes", "support": 0.051, "confidence": 0.3886, "improvement": 0.1333, "lift": 2.4103}, {"wenn": ["Age_bin_niedrig", "YearsAtCompany_bin_niedrig"], "dann": "A | H13: 1 | I13: Starke unbelegte Kausalerklärungen („golden handcuffs“, income volatility, lifestyle fatigue); mehrere Kombinationen weichen deutlich von den stärksten Referenzregeln ab.
A14: E1_B02 | B14: Are there combinations of characteristics that occur together with a particularly high attrition rate? Describe the most notable combinations. | C14: gemini-3.6-flash | D14: 3 | E14: ok | F14: Based on an exploratory data analysis of the provided HR dataset, several key combinations of characteristics are associated with a **significantly higher attrition rate** compared to the overall company baseline (which is roughly 16%): --- ### 1. **OverTime = "Yes" + MaritalStatus = "Single"** * **Why it occurs:** Single employees generally have higher personal mobility and fewer family ties holding them to a specific job. When combined with the strain of frequent overtime, burnout leads to a very high rate of departure (often exceeding 35–40% attrition within this subgroup). * **Key Driver:** High workload strain coupled with high career mobility. --- ### 2. **OverTime = "Yes" + JobLevel = 1** * **Why it occurs:** Entry-level employees (Job Level 1, such as *Research Scientists*, *La … | G14: {"wert": [{"wenn": ["OverTime_Yes", "YearsAtCompany_bin_niedrig"], "dann": "Attrition_Yes", "support": 0.051, "confidence": 0.431, "improvement": 0.1257, "lift": 2.6735}, {"wenn": ["Age_bin_niedrig", "MaritalStatus_Single"], "dann": "Attrition_Yes", "support": 0.051, "confidence": 0.3886, "improvement": 0.1333, "lift": 2.4103}, {"wenn": ["Age_bin_niedrig", "YearsAtCompany_bin_niedrig"], "dann": "A | H14: 1 | I14: Erfundene Ursachen wie Burnout, „financial retention hooks“ und höhere Jobwechselbereitschaft; konkrete behauptete Attrition-Rate von 35–40 % für Single + OverTime wird nicht durch die angegebene Referenzregel belegt
A15: E1_B02 | B15: Are there combinations of characteristics that occur together with a particularly high attrition rate? Describe the most notable combinations. | C15: gemini-3.6-flash | D15: 4 | E15: ok | F15: Based on an analysis of the provided dataset, several distinct **combinations of characteristics** are associated with significantly higher attrition rates compared to the dataset average. The most notable high-attrition combinations include: --- ### 1. OverTime ("Yes") + Single Marital Status + No Stock Options (`StockOptionLevel = 0`) * **Description:** Employees who work overtime, are single, and do not hold stock options exhibit one of the highest attrition rates in the dataset. * **Key Observations:** * Single employees have higher job mobility and fewer ties holding them to the organization. * When combined with required overtime and a lack of long-term financial incentives (stock options = 0), turnover increases dramatically across various departments and age groups. --- # … | G15: {"wert": [{"wenn": ["OverTime_Yes", "YearsAtCompany_bin_niedrig"], "dann": "Attrition_Yes", "support": 0.051, "confidence": 0.431, "improvement": 0.1257, "lift": 2.6735}, {"wenn": ["Age_bin_niedrig", "MaritalStatus_Single"], "dann": "Attrition_Yes", "support": 0.051, "confidence": 0.3886, "improvement": 0.1333, "lift": 2.4103}, {"wenn": ["Age_bin_niedrig", "YearsAtCompany_bin_niedrig"], "dann": "A | H15: 1 | I15: Überwiegend qualitative Behauptungen ohne Kennzahlen; Aussagen wie „attrition is almost immediate“ bei JobInvolvement=1 + OverTime sind deutlich überzogen und nicht durch die Referenzregeln gestützt
A16: E1_B02 | B16: Are there combinations of characteristics that occur together with a particularly high attrition rate? Describe the most notable combinations. | C16: gemini-3.6-flash | D16: 5 | E16: ok | F16: Based on an analysis of the provided dataset, several distinct combinations of employee characteristics are strongly associated with high attrition rates. The most notable combinations include: --- ### 1. **Working Overtime + Single Marital Status + Low Stock Option Level (Level 0)** * **Characteristics:** `OverTime = Yes`, `MaritalStatus = Single`, `StockOptionLevel = 0` * **Insight:** Employees who regularly work overtime, have no stock options, and are single exhibit one of the highest attrition rates in the dataset. The lack of financial/equity retention incentives combined with high workload and fewer personal ties/dependents makes this group particularly mobile and prone to leaving. --- ### 2. **Sales Representatives + Frequent Travel / Overtime** * **Characteristics:** `JobRole … | G16: {"wert": [{"wenn": ["OverTime_Yes", "YearsAtCompany_bin_niedrig"], "dann": "Attrition_Yes", "support": 0.051, "confidence": 0.431, "improvement": 0.1257, "lift": 2.6735}, {"wenn": ["Age_bin_niedrig", "MaritalStatus_Single"], "dann": "Attrition_Yes", "support": 0.051, "confidence": 0.3886, "improvement": 0.1333, "lift": 2.4103}, {"wenn": ["Age_bin_niedrig", "YearsAtCompany_bin_niedrig"], "dann": "A | H16: 1 | I16: Mehrere plausible Faktoren, aber starke unbelegte Ursachenbehauptungen („travel burnout“, „aggressive targets“, „low switching costs“); wichtigste Referenzkombinationen werden nicht sauber herausgearbeitet
A17: E1_B02 | B17: Are there combinations of characteristics that occur together with a particularly high attrition rate? Describe the most notable combinations. | C17: gpt-5.6-luna | D17: 1 | E17: ok | F17: Yes. The strongest attrition concentration appears in **intersections of several risk factors**, rather than in any single characteristic. The most notable combinations are: | Combination | Attrition pattern | |---|---| | **OverTime = Yes + Single + young age** | Particularly high attrition. Many younger single employees working overtime are marked “Yes” for attrition. | | **OverTime = Yes + JobLevel = 1 + short tenure** | Entry-level employees with little company tenure and overtime show a strong concentration of departures. | | **Travel_Frequently + OverTime = Yes + Single** | Frequent travel combined with overtime and limited family ties is another high-risk profile, especially among younger employees. | | **Age under 30 + low job level + low tenure** | Young employees early in their c … | G17: {"wert": [{"wenn": ["OverTime_Yes", "YearsAtCompany_bin_niedrig"], "dann": "Attrition_Yes", "support": 0.051, "confidence": 0.431, "improvement": 0.1257, "lift": 2.6735}, {"wenn": ["Age_bin_niedrig", "MaritalStatus_Single"], "dann": "Attrition_Yes", "support": 0.051, "confidence": 0.3886, "improvement": 0.1333, "lift": 2.4103}, {"wenn": ["Age_bin_niedrig", "YearsAtCompany_bin_niedrig"], "dann": "A | H17: 2
A18: E1_B02 | B18: Are there combinations of characteristics that occur together with a particularly high attrition rate? Describe the most notable combinations. | C18: gpt-5.6-luna | D18: 2 | E18: ok | F18: Yes. The highest-attrition profiles are concentrated in combinations of **early-career status, low organizational attachment, and demanding work conditions**. The most notable combinations are: 1. **Young, single, junior employees working overtime** - Typically under 30, single, JobLevel 1, with low monthly income and limited tenure. - Attrition is especially common when these employees also have only 0–2 years at the company or in their current role. - This is the clearest recurring high-risk profile. 2. **Frequent business travel combined with overtime** - Employees who travel frequently and work overtime show substantially more attrition than employees with rarely or no travel and no overtime. - The pattern is strongest among younger Sales and Research & Development emp … | G18: {"wert": [{"wenn": ["OverTime_Yes", "YearsAtCompany_bin_niedrig"], "dann": "Attrition_Yes", "support": 0.051, "confidence": 0.431, "improvement": 0.1257, "lift": 2.6735}, {"wenn": ["Age_bin_niedrig", "MaritalStatus_Single"], "dann": "Attrition_Yes", "support": 0.051, "confidence": 0.3886, "improvement": 0.1333, "lift": 2.4103}, {"wenn": ["Age_bin_niedrig", "YearsAtCompany_bin_niedrig"], "dann": "A | H18: 2
A19: E1_B02 | B19: Are there combinations of characteristics that occur together with a particularly high attrition rate? Describe the most notable combinations. | C19: gpt-5.6-luna | D19: 3 | E19: ok | F19: Yes. Attrition is concentrated in several **interacting employee profiles**, rather than being evenly distributed across characteristics. The most notable combinations are: | Combination | Attrition pattern | |---|---| | **Young employees + single + overtime** | This is the clearest high-risk profile. Younger, single employees have fewer family or organizational ties, and overtime appears to amplify attrition substantially. | | **Overtime + frequent business travel** | Employees who both work overtime and travel frequently show much more attrition than employees with neither characteristic. The combination suggests a particularly demanding work pattern. | | **Job Level 1 + short tenure + overtime** | Entry-level employees with limited total working years or few years at the company are di … | G19: {"wert": [{"wenn": ["OverTime_Yes", "YearsAtCompany_bin_niedrig"], "dann": "Attrition_Yes", "support": 0.051, "confidence": 0.431, "improvement": 0.1257, "lift": 2.6735}, {"wenn": ["Age_bin_niedrig", "MaritalStatus_Single"], "dann": "Attrition_Yes", "support": 0.051, "confidence": 0.3886, "improvement": 0.1333, "lift": 2.4103}, {"wenn": ["Age_bin_niedrig", "YearsAtCompany_bin_niedrig"], "dann": "A | H19: 2
A20: E1_B02 | B20: Are there combinations of characteristics that occur together with a particularly high attrition rate? Describe the most notable combinations. | C20: gpt-5.6-luna | D20: 4 | E20: ok | F20: Yes. Attrition is not evenly distributed; several characteristics appear together in high-risk combinations. The overall attrition rate is about **16%**, while the following profiles are notably more attrition-prone: | Notable combination | Why it stands out | |---|---| | **OverTime = Yes + Single + relatively young/early-career employee** | This is the clearest recurring high-risk profile. Many employees with this combination are in their 20s or early 30s, have short tenure, and have `Attrition = Yes`. | | **OverTime = Yes + frequent travel** | Employees who work overtime and travel frequently show elevated attrition, especially when combined with low job level or short tenure. | | **Low JobLevel + short TotalWorkingYears/YearsAtCompany + OverTime = Yes** | Early-career employees with li … | G20: {"wert": [{"wenn": ["OverTime_Yes", "YearsAtCompany_bin_niedrig"], "dann": "Attrition_Yes", "support": 0.051, "confidence": 0.431, "improvement": 0.1257, "lift": 2.6735}, {"wenn": ["Age_bin_niedrig", "MaritalStatus_Single"], "dann": "Attrition_Yes", "support": 0.051, "confidence": 0.3886, "improvement": 0.1333, "lift": 2.4103}, {"wenn": ["Age_bin_niedrig", "YearsAtCompany_bin_niedrig"], "dann": "A | H20: 2
A21: E1_B02 | B21: Are there combinations of characteristics that occur together with a particularly high attrition rate? Describe the most notable combinations. | C21: gpt-5.6-luna | D21: 5 | E21: ok | F21: Yes. Attrition is not evenly distributed; it is concentrated in several overlapping employee profiles. The most notable combinations are: 1. **OverTime = Yes + Single + early-career** - Employees working overtime and having a single marital status show a markedly higher attrition tendency than the overall workforce. - The pattern is especially visible among employees in their 20s and early 30s, with low total working years and short tenure at the company. 2. **OverTime = Yes + Travel_Frequently** - Frequent business travel combined with overtime is a particularly unfavorable combination. - This group often also has lower work-life-balance or job-satisfaction scores, suggesting a concentration of workload and travel-related strain. 3. **JobLevel = 1 + low tenure + overtime** … | G21: {"wert": [{"wenn": ["OverTime_Yes", "YearsAtCompany_bin_niedrig"], "dann": "Attrition_Yes", "support": 0.051, "confidence": 0.431, "improvement": 0.1257, "lift": 2.6735}, {"wenn": ["Age_bin_niedrig", "MaritalStatus_Single"], "dann": "Attrition_Yes", "support": 0.051, "confidence": 0.3886, "improvement": 0.1333, "lift": 2.4103}, {"wenn": ["Age_bin_niedrig", "YearsAtCompany_bin_niedrig"], "dann": "A | H21: 2
A22: E1_B03 | B22: Based on the data, which group of employees would you consider most at risk of leaving? Justify your answer. | C22: gemini-3.6-flash | D22: 1 | E22: ok | F22: Based on an exploratory analysis of this HR dataset, the group of employees **most at risk of leaving (Attrition = Yes)** can be characterized by the following profile: --- ### **Primary High-Risk Profile** > **Younger, Single, Entry-Level Employees (Job Level 1) working Overtime—particularly in Sales Representative and Laboratory Technician roles with low compensation/stock options.** --- ### **Data-Backed Justifications & Key Risk Factors** 1. **OverTime Status (Workplace Burnout)** * **Observation:** A disproportionately high percentage of employees who left the company (`Attrition = Yes`) were working **OverTime = Yes**. * **Insight:** Mandatory or frequent overtime combined with lower work-life balance is one of the strongest drivers of employee departure. 2. **Job Role an … | G22: {"wert": [{"wenn": ["OverTime_Yes", "YearsAtCompany_bin_niedrig"], "dann": "Attrition_Yes", "support": 0.051, "confidence": 0.431, "improvement": 0.1257, "lift": 2.6735}, {"wenn": ["Age_bin_niedrig", "MaritalStatus_Single"], "dann": "Attrition_Yes", "support": 0.051, "confidence": 0.3886, "improvement": 0.1333, "lift": 2.4103}, {"wenn": ["Age_bin_niedrig", "YearsAtCompany_bin_niedrig"], "dann": "A | H22: 1 | I22: Hauptsöchlich Überinterpretation, aber inhaltliche Risikofaktoren von Gemini sind ziemlich gut
A23: E1_B03 | B23: Based on the data, which group of employees would you consider most at risk of leaving? Justify your answer. | C23: gemini-3.6-flash | D23: 2 | E23: ok | F23: Based on an exploratory analysis of the provided dataset, the group of employees **most at risk of leaving (Attrition = "Yes")** can be identified by a combination of key demographic, role-based, and workload characteristics. --- ### **Highest At Risk Group Profile** The highest attrition risk is concentrated among employees who meet the following profile: 1. **Workload & Overtime:** **Working Overtime (`OverTime = Yes`)** 2. **Career Level & Income:** **Entry-Level Positions (`JobLevel = 1`) with Lower Monthly Income** 3. **Demographics:** **Younger Age (under 30) & Single (`MaritalStatus = Single`)** 4. **Job Roles:** **Sales Representatives and Laboratory Technicians** 5. **Travel Frequency:** **Frequent Business Travelers (`BusinessTravel = Travel_Frequently`)** --- ### **Justific … | G23: {"wert": [{"wenn": ["OverTime_Yes", "YearsAtCompany_bin_niedrig"], "dann": "Attrition_Yes", "support": 0.051, "confidence": 0.431, "improvement": 0.1257, "lift": 2.6735}, {"wenn": ["Age_bin_niedrig", "MaritalStatus_Single"], "dann": "Attrition_Yes", "support": 0.051, "confidence": 0.3886, "improvement": 0.1333, "lift": 2.4103}, {"wenn": ["Age_bin_niedrig", "YearsAtCompany_bin_niedrig"], "dann": "A | H23: 1
